<?xml version="1.0"?>
<robot xmlns:xacro="http://www.ros.org/wiki/xacro" name="turtlebot_arm">
  
  <!-- Base link for the robot -->
  <link name="base_footprint"/>
  
  <joint name="base_footprint_joint" type="fixed">
    <parent link="base_footprint"/>
    <child link="base_link"/>
    <origin xyz="0 0 0.010" rpy="0 0 0"/>
  </joint>
  
  <!-- Base link -->
  <link name="base_link">
    <visual>
      <geometry>
        <box size="0.2 0.2 0.1"/>
      </geometry>
      <material name="base_material">
        <color rgba="0.2 0.2 0.2 1"/>
      </material>
    </visual>
    <collision>
      <geometry>
        <box size="0.2 0.2 0.1"/>
      </geometry>
    </collision>
    <inertial>
      <mass value="5.0"/>
      <inertia ixx="0.1" ixy="0.0" ixz="0.0" iyy="0.1" iyz="0.0" izz="0.1"/>
    </inertial>
  </link>
  
  <!-- Left wheel -->
  <link name="left_wheel">
    <visual>
      <geometry>
        <cylinder radius="0.033" length="0.03"/>
      </geometry>
      <material name="wheel_material">
        <color rgba="0.1 0.1 0.1 1"/>
      </material>
    </visual>
    <collision>
      <geometry>
        <cylinder radius="0.033" length="0.03"/>
      </geometry>
    </collision>
    <inertial>
      <mass value="0.5"/>
      <inertia ixx="0.001" ixy="0.0" ixz="0.0" iyy="0.001" iyz="0.0" izz="0.001"/>
    </inertial>
  </link>
  
  <joint name="left_wheel_joint" type="continuous">
    <parent link="base_link"/>
    <child link="left_wheel"/>
    <origin xyz="0 0.1 0" rpy="-1.5708 0 0"/>
    <axis xyz="0 1 0"/>
  </joint>
  
  <!-- Right wheel -->
  <link name="right_wheel">
    <visual>
      <geometry>
        <cylinder radius="0.033" length="0.03"/>
      </geometry>
      <material name="wheel_material">
        <color rgba="0.1 0.1 0.1 1"/>
      </material>
    </visual>
    <collision>
      <geometry>
        <cylinder radius="0.033" length="0.03"/>
      </geometry>
    </collision>
    <inertial>
      <mass value="0.5"/>
      <inertia ixx="0.001" ixy="0.0" ixz="0.0" iyy="0.001" iyz="0.0" izz="0.001"/>
    </inertial>
  </link>
  
  <joint name="right_wheel_joint" type="continuous">
    <parent link="base_link"/>
    <child link="right_wheel"/>
    <origin xyz="0 -0.1 0" rpy="-1.5708 0 0"/>
    <axis xyz="0 1 0"/>
  </joint>
  
  <!-- Caster wheel -->
  <link name="caster_wheel">
    <visual>
      <geometry>
        <sphere radius="0.02"/>
      </geometry>
      <material name="wheel_material"/>
    </visual>
    <collision>
      <geometry>
        <sphere radius="0.02"/>
      </geometry>
    </collision>
    <inertial>
      <mass value="0.1"/>
      <inertia ixx="0.0001" ixy="0.0" ixz="0.0" iyy="0.0001" iyz="0.0" izz="0.0001"/>
    </inertial>
  </link>
  
  <joint name="caster_wheel_joint" type="fixed">
    <parent link="base_link"/>
    <child link="caster_wheel"/>
    <origin xyz="0.1 0 -0.05" rpy="0 0 0"/>
  </joint>
  
  <!-- Arm base link - attached to top of robot -->
  <link name="arm_base_link">
    <visual>
      <geometry>
        <cylinder radius="0.05" length="0.1"/>
      </geometry>
      <material name="arm_material">
        <color rgba="0.8 0.8 0.8 1"/>
      </material>
    </visual>
    <collision>
      <geometry>
        <cylinder radius="0.05" length="0.1"/>
      </geometry>
    </collision>
    <inertial>
      <mass value="0.5"/>
      <inertia ixx="0.001" ixy="0.0" ixz="0.0" iyy="0.001" iyz="0.0" izz="0.001"/>
    </inertial>
  </link>
  
  <joint name="arm_base_joint" type="fixed">
    <parent link="base_link"/>
    <child link="arm_base_link"/>
    <origin xyz="0.1 0 0.15" rpy="0 0 0"/>
  </joint>
  
  <!-- Arm joint 1 - Shoulder pan -->
  <link name="arm_link1">
    <visual>
      <geometry>
        <box size="0.08 0.08 0.15"/>
      </geometry>
      <material name="arm_material"/>
    </visual>
    <collision>
      <geometry>
        <box size="0.08 0.08 0.15"/>
      </geometry>
    </collision>
    <inertial>
      <mass value="0.3"/>
      <inertia ixx="0.001" ixy="0.0" ixz="0.0" iyy="0.001" iyz="0.0" izz="0.001"/>
    </inertial>
  </link>
  
  <joint name="arm_joint1" type="revolute">
    <parent link="arm_base_link"/>
    <child link="arm_link1"/>
    <origin xyz="0 0 0.05" rpy="0 0 0"/>
    <axis xyz="0 0 1"/>
    <limit lower="-3.14159" upper="3.14159" effort="10" velocity="1.0"/>
  </joint>
  
  <!-- Arm joint 2 - Shoulder lift -->
  <link name="arm_link2">
    <visual>
      <geometry>
        <box size="0.06 0.15 0.06"/>
      </geometry>
      <material name="arm_material"/>
    </visual>
    <collision>
      <geometry>
        <box size="0.06 0.15 0.06"/>
      </geometry>
    </collision>
    <inertial>
      <mass value="0.25"/>
      <inertia ixx="0.001" ixy="0.0" ixz="0.0" iyy="0.001" iyz="0.0" izz="0.001"/>
    </inertial>
  </link>
  
  <joint name="arm_joint2" type="revolute">
    <parent link="arm_link1"/>
    <child link="arm_link2"/>
    <origin xyz="0 0.075 0" rpy="0 0 0"/>
    <axis xyz="0 1 0"/>
    <limit lower="-1.57" upper="1.57" effort="10" velocity="1.0"/>
  </joint>
  
  <!-- Arm joint 3 - Elbow -->
  <link name="arm_link3">
    <visual>
      <geometry>
        <box size="0.05 0.12 0.05"/>
      </geometry>
      <material name="arm_material"/>
    </visual>
    <collision>
      <geometry>
        <box size="0.05 0.12 0.05"/>
      </geometry>
    </collision>
    <inertial>
      <mass value="0.2"/>
      <inertia ixx="0.001" ixy="0.0" ixz="0.0" iyy="0.001" iyz="0.0" izz="0.001"/>
    </inertial>
  </link>
  
  <joint name="arm_joint3" type="revolute">
    <parent link="arm_link2"/>
    <child link="arm_link3"/>
    <origin xyz="0 0.06 0" rpy="0 0 0"/>
    <axis xyz="0 1 0"/>
    <limit lower="-2.0" upper="2.0" effort="8" velocity="1.0"/>
  </joint>
  
  <!-- Arm joint 4 - Wrist roll -->
  <link name="arm_link4">
    <visual>
      <geometry>
        <cylinder radius="0.03" length="0.08"/>
      </geometry>
      <material name="arm_material"/>
    </visual>
    <collision>
      <geometry>
        <cylinder radius="0.03" length="0.08"/>
      </geometry>
    </collision>
    <inertial>
      <mass value="0.15"/>
      <inertia ixx="0.0005" ixy="0.0" ixz="0.0" iyy="0.0005" iyz="0.0" izz="0.0005"/>
    </inertial>
  </link>
  
  <joint name="arm_joint4" type="revolute">
    <parent link="arm_link3"/>
    <child link="arm_link4"/>
    <origin xyz="0 0.06 0" rpy="0 0 0"/>
    <axis xyz="0 0 1"/>
    <limit lower="-3.14159" upper="3.14159" effort="5" velocity="1.5"/>
  </joint>
  
  <!-- Arm joint 5 - Wrist pitch -->
  <link name="arm_link5">
    <visual>
      <geometry>
        <box size="0.04 0.06 0.04"/>
      </geometry>
      <material name="arm_material"/>
    </visual>
    <collision>
      <geometry>
        <box size="0.04 0.06 0.04"/>
      </geometry>
    </collision>
    <inertial>
      <mass value="0.1"/>
      <inertia ixx="0.0001" ixy="0.0" ixz="0.0" iyy="0.0001" iyz="0.0" izz="0.0001"/>
    </inertial>
  </link>
  
  <joint name="arm_joint5" type="revolute">
    <parent link="arm_link4"/>
    <child link="arm_link5"/>
    <origin xyz="0 0.03 0" rpy="0 0 0"/>
    <axis xyz="0 1 0"/>
    <limit lower="-1.57" upper="1.57" effort="5" velocity="1.5"/>
  </joint>
  
  <!-- End effector - Gripper/Sampler -->
  <link name="end_effector_link">
    <visual>
      <geometry>
        <box size="0.05 0.05 0.1"/>
      </geometry>
      <material name="gripper_material">
        <color rgba="0.9 0.1 0.1 1"/>
      </material>
    </visual>
    <collision>
      <geometry>
        <box size="0.05 0.05 0.1"/>
      </geometry>
    </collision>
    <inertial>
      <mass value="0.2"/>
      <inertia ixx="0.0001" ixy="0.0" ixz="0.0" iyy="0.0001" iyz="0.0" izz="0.0001"/>
    </inertial>
  </link>
  
  <joint name="end_effector_joint" type="fixed">
    <parent link="arm_link5"/>
    <child link="end_effector_link"/>
    <origin xyz="0 0.03 0" rpy="0 0 0"/>
  </joint>
  
  <!-- Gazebo plugins for ros2_control -->
  <gazebo>
    <plugin filename="libgazebo_ros2_control.so" name="gazebo_ros2_control">
      <parameters>$(find farm_control)/config/ros2_control.yaml</parameters>
    </plugin>
  </gazebo>
  
  <!-- Material definitions for Gazebo -->
  <gazebo reference="base_link">
    <material>Gazebo/Grey</material>
  </gazebo>
  
  <gazebo reference="arm_base_link">
    <material>Gazebo/Silver</material>
  </gazebo>
  
  <gazebo reference="arm_link1">
    <material>Gazebo/Silver</material>
  </gazebo>
  
  <gazebo reference="arm_link2">
    <material>Gazebo/Silver</material>
  </gazebo>
  
  <gazebo reference="arm_link3">
    <material>Gazebo/Silver</material>
  </gazebo>
  
  <gazebo reference="arm_link4">
    <material>Gazebo/Silver</material>
  </gazebo>
  
  <gazebo reference="arm_link5">
    <material>Gazebo/Silver</material>
  </gazebo>
  
  <gazebo reference="end_effector_link">
    <material>Gazebo/Red</material>
  </gazebo>
  
</robot>
